
Using TensorFlow backend.
Using TensorFlow backend.
Traceback (most recent call last):
  File "C:\Users\luis_\anaconda3\envs\tf-optuna2\lib\site-packages\IPython\core\interactiveshell.py", line 3457, in run_code
  File "C:\Users\luis_\AppData\Local\Temp\ipykernel_21356\3057074518.py", line 1, in <module>
    from tensorflow.keras.models import Sequential
  File "C:\Users\luis_\anaconda3\envs\tf-optuna2\lib\site-packages\tensorflow\__init__.py", line 50, in __getattr__
    from tensorflow._api.v1 import layers
  File "C:\Users\luis_\anaconda3\envs\tf-optuna2\lib\site-packages\tensorflow\__init__.py", line 44, in _load
    from tensorflow._api.v1 import feature_column
  File "C:\Users\luis_\anaconda3\envs\tf-optuna2\lib\importlib\__init__.py", line 127, in import_module
    return _bootstrap._gcd_import(name[level:], package, level)
ModuleNotFoundError: No module named 'tensorflow_core'
During handling of the above exception, another exception occurred:
Traceback (most recent call last):
  File "C:\Users\luis_\anaconda3\envs\tf-optuna2\lib\site-packages\IPython\core\interactiveshell.py", line 2077, in showtraceback
AttributeError: 'ModuleNotFoundError' object has no attribute '_render_traceback_'
During handling of the above exception, another exception occurred:
Traceback (most recent call last):
  File "C:\Users\luis_\anaconda3\envs\tf-optuna2\lib\site-packages\IPython\core\ultratb.py", line 1101, in get_records
  File "C:\Users\luis_\anaconda3\envs\tf-optuna2\lib\site-packages\IPython\core\ultratb.py", line 248, in wrapped
  File "C:\Users\luis_\anaconda3\envs\tf-optuna2\lib\site-packages\IPython\core\ultratb.py", line 281, in _fixed_getinnerframes
  File "C:\Users\luis_\anaconda3\envs\tf-optuna2\lib\inspect.py", line 1502, in getinnerframes
    frameinfo = (tb.tb_frame,) + getframeinfo(tb, context)
  File "C:\Users\luis_\anaconda3\envs\tf-optuna2\lib\inspect.py", line 1460, in getframeinfo
    filename = getsourcefile(frame) or getfile(frame)
  File "C:\Users\luis_\anaconda3\envs\tf-optuna2\lib\inspect.py", line 696, in getsourcefile
    if getattr(getmodule(object, filename), '__loader__', None) is not None:
  File "C:\Users\luis_\anaconda3\envs\tf-optuna2\lib\inspect.py", line 733, in getmodule
    if ismodule(module) and hasattr(module, '__file__'):
  File "C:\Users\luis_\anaconda3\envs\tf-optuna2\lib\site-packages\tensorflow\__init__.py", line 50, in __getattr__
    from tensorflow._api.v1 import layers
  File "C:\Users\luis_\anaconda3\envs\tf-optuna2\lib\site-packages\tensorflow\__init__.py", line 44, in _load
    from tensorflow._api.v1 import feature_column
  File "C:\Users\luis_\anaconda3\envs\tf-optuna2\lib\importlib\__init__.py", line 127, in import_module
    return _bootstrap._gcd_import(name[level:], package, level)
  File "<frozen importlib._bootstrap>", line 1006, in _gcd_import
  File "<frozen importlib._bootstrap>", line 983, in _find_and_load
  File "<frozen importlib._bootstrap>", line 953, in _find_and_load_unlocked
  File "<frozen importlib._bootstrap>", line 219, in _call_with_frames_removed
  File "<frozen importlib._bootstrap>", line 1006, in _gcd_import
  File "<frozen importlib._bootstrap>", line 983, in _find_and_load
  File "<frozen importlib._bootstrap>", line 965, in _find_and_load_unlocked
ModuleNotFoundError: No module named 'tensorflow_core'
Traceback (most recent call last):
  File "C:\Users\luis_\anaconda3\envs\tf-optuna2\lib\site-packages\IPython\core\interactiveshell.py", line 3457, in run_code
  File "C:\Users\luis_\AppData\Local\Temp\ipykernel_21356\3057074518.py", line 1, in <module>
    from tensorflow.keras.models import Sequential
  File "C:\Users\luis_\anaconda3\envs\tf-optuna2\lib\site-packages\tensorflow\__init__.py", line 50, in __getattr__
    from tensorflow._api.v1 import layers
  File "C:\Users\luis_\anaconda3\envs\tf-optuna2\lib\site-packages\tensorflow\__init__.py", line 44, in _load
    from tensorflow._api.v1 import feature_column
  File "C:\Users\luis_\anaconda3\envs\tf-optuna2\lib\importlib\__init__.py", line 127, in import_module
    return _bootstrap._gcd_import(name[level:], package, level)
ModuleNotFoundError: No module named 'tensorflow_core'
During handling of the above exception, another exception occurred:
Traceback (most recent call last):
  File "C:\Users\luis_\anaconda3\envs\tf-optuna2\lib\site-packages\IPython\core\interactiveshell.py", line 2077, in showtraceback
AttributeError: 'ModuleNotFoundError' object has no attribute '_render_traceback_'
During handling of the above exception, another exception occurred:
Traceback (most recent call last):
  File "C:\Users\luis_\anaconda3\envs\tf-optuna2\lib\site-packages\IPython\core\interactiveshell.py", line 3377, in run_ast_nodes
  File "C:\Users\luis_\anaconda3\envs\tf-optuna2\lib\site-packages\IPython\core\interactiveshell.py", line 3474, in run_code
  File "C:\Users\luis_\anaconda3\envs\tf-optuna2\lib\site-packages\IPython\core\interactiveshell.py", line 2080, in showtraceback
  File "C:\Users\luis_\anaconda3\envs\tf-optuna2\lib\site-packages\IPython\core\ultratb.py", line 1368, in structured_traceback
  File "C:\Users\luis_\anaconda3\envs\tf-optuna2\lib\site-packages\IPython\core\ultratb.py", line 1268, in structured_traceback
  File "C:\Users\luis_\anaconda3\envs\tf-optuna2\lib\site-packages\IPython\core\ultratb.py", line 1125, in structured_traceback
  File "C:\Users\luis_\anaconda3\envs\tf-optuna2\lib\site-packages\IPython\core\ultratb.py", line 1082, in format_exception_as_a_whole
  File "C:\Users\luis_\anaconda3\envs\tf-optuna2\lib\site-packages\IPython\core\ultratb.py", line 382, in find_recursion
TypeError: object of type 'NoneType' has no len()
During handling of the above exception, another exception occurred:
Traceback (most recent call last):
  File "C:\Users\luis_\anaconda3\envs\tf-optuna2\lib\site-packages\IPython\core\interactiveshell.py", line 2077, in showtraceback
AttributeError: 'TypeError' object has no attribute '_render_traceback_'
During handling of the above exception, another exception occurred:
Traceback (most recent call last):
  File "C:\Users\luis_\anaconda3\envs\tf-optuna2\lib\site-packages\IPython\core\ultratb.py", line 1101, in get_records
  File "C:\Users\luis_\anaconda3\envs\tf-optuna2\lib\site-packages\IPython\core\ultratb.py", line 248, in wrapped
  File "C:\Users\luis_\anaconda3\envs\tf-optuna2\lib\site-packages\IPython\core\ultratb.py", line 281, in _fixed_getinnerframes
  File "C:\Users\luis_\anaconda3\envs\tf-optuna2\lib\inspect.py", line 1502, in getinnerframes
    frameinfo = (tb.tb_frame,) + getframeinfo(tb, context)
  File "C:\Users\luis_\anaconda3\envs\tf-optuna2\lib\inspect.py", line 1460, in getframeinfo
    filename = getsourcefile(frame) or getfile(frame)
  File "C:\Users\luis_\anaconda3\envs\tf-optuna2\lib\inspect.py", line 696, in getsourcefile
    if getattr(getmodule(object, filename), '__loader__', None) is not None:
  File "C:\Users\luis_\anaconda3\envs\tf-optuna2\lib\inspect.py", line 733, in getmodule
    if ismodule(module) and hasattr(module, '__file__'):
  File "C:\Users\luis_\anaconda3\envs\tf-optuna2\lib\site-packages\tensorflow\__init__.py", line 50, in __getattr__
    from tensorflow._api.v1 import layers
  File "C:\Users\luis_\anaconda3\envs\tf-optuna2\lib\site-packages\tensorflow\__init__.py", line 44, in _load
    from tensorflow._api.v1 import feature_column
  File "C:\Users\luis_\anaconda3\envs\tf-optuna2\lib\importlib\__init__.py", line 127, in import_module
    return _bootstrap._gcd_import(name[level:], package, level)
  File "<frozen importlib._bootstrap>", line 1006, in _gcd_import
  File "<frozen importlib._bootstrap>", line 983, in _find_and_load
  File "<frozen importlib._bootstrap>", line 953, in _find_and_load_unlocked
  File "<frozen importlib._bootstrap>", line 219, in _call_with_frames_removed
  File "<frozen importlib._bootstrap>", line 1006, in _gcd_import
  File "<frozen importlib._bootstrap>", line 983, in _find_and_load
  File "<frozen importlib._bootstrap>", line 965, in _find_and_load_unlocked
ModuleNotFoundError: No module named 'tensorflow_core'
Traceback (most recent call last):
  File "C:\Users\luis_\anaconda3\envs\tf-optuna2\lib\site-packages\IPython\core\interactiveshell.py", line 3457, in run_code
  File "C:\Users\luis_\AppData\Local\Temp\ipykernel_21356\3057074518.py", line 1, in <module>
    from tensorflow.keras.models import Sequential
  File "C:\Users\luis_\anaconda3\envs\tf-optuna2\lib\site-packages\tensorflow\__init__.py", line 50, in __getattr__
    from tensorflow._api.v1 import layers
  File "C:\Users\luis_\anaconda3\envs\tf-optuna2\lib\site-packages\tensorflow\__init__.py", line 44, in _load
    from tensorflow._api.v1 import feature_column
  File "C:\Users\luis_\anaconda3\envs\tf-optuna2\lib\importlib\__init__.py", line 127, in import_module
    return _bootstrap._gcd_import(name[level:], package, level)
ModuleNotFoundError: No module named 'tensorflow_core'
During handling of the above exception, another exception occurred:
Traceback (most recent call last):
  File "C:\Users\luis_\anaconda3\envs\tf-optuna2\lib\site-packages\IPython\core\interactiveshell.py", line 2077, in showtraceback
AttributeError: 'ModuleNotFoundError' object has no attribute '_render_traceback_'
During handling of the above exception, another exception occurred:
Traceback (most recent call last):
  File "C:\Users\luis_\anaconda3\envs\tf-optuna2\lib\site-packages\IPython\core\interactiveshell.py", line 3377, in run_ast_nodes
  File "C:\Users\luis_\anaconda3\envs\tf-optuna2\lib\site-packages\IPython\core\interactiveshell.py", line 3474, in run_code
  File "C:\Users\luis_\anaconda3\envs\tf-optuna2\lib\site-packages\IPython\core\interactiveshell.py", line 2080, in showtraceback
  File "C:\Users\luis_\anaconda3\envs\tf-optuna2\lib\site-packages\IPython\core\ultratb.py", line 1368, in structured_traceback
  File "C:\Users\luis_\anaconda3\envs\tf-optuna2\lib\site-packages\IPython\core\ultratb.py", line 1268, in structured_traceback
  File "C:\Users\luis_\anaconda3\envs\tf-optuna2\lib\site-packages\IPython\core\ultratb.py", line 1125, in structured_traceback
  File "C:\Users\luis_\anaconda3\envs\tf-optuna2\lib\site-packages\IPython\core\ultratb.py", line 1082, in format_exception_as_a_whole
  File "C:\Users\luis_\anaconda3\envs\tf-optuna2\lib\site-packages\IPython\core\ultratb.py", line 382, in find_recursion
TypeError: object of type 'NoneType' has no len()
During handling of the above exception, another exception occurred:
Traceback (most recent call last):
  File "C:\Users\luis_\anaconda3\envs\tf-optuna2\lib\site-packages\IPython\core\interactiveshell.py", line 2077, in showtraceback
AttributeError: 'TypeError' object has no attribute '_render_traceback_'
During handling of the above exception, another exception occurred:
Traceback (most recent call last):
  File "C:\Users\luis_\anaconda3\envs\tf-optuna2\lib\site-packages\IPython\core\interactiveshell.py", line 2960, in _run_cell
  File "C:\Users\luis_\anaconda3\envs\tf-optuna2\lib\site-packages\IPython\core\async_helpers.py", line 78, in _pseudo_sync_runner
  File "C:\Users\luis_\anaconda3\envs\tf-optuna2\lib\site-packages\IPython\core\interactiveshell.py", line 3186, in run_cell_async
  File "C:\Users\luis_\anaconda3\envs\tf-optuna2\lib\site-packages\IPython\core\interactiveshell.py", line 3396, in run_ast_nodes
  File "C:\Users\luis_\anaconda3\envs\tf-optuna2\lib\site-packages\IPython\core\interactiveshell.py", line 2080, in showtraceback
  File "C:\Users\luis_\anaconda3\envs\tf-optuna2\lib\site-packages\IPython\core\ultratb.py", line 1368, in structured_traceback
  File "C:\Users\luis_\anaconda3\envs\tf-optuna2\lib\site-packages\IPython\core\ultratb.py", line 1268, in structured_traceback
  File "C:\Users\luis_\anaconda3\envs\tf-optuna2\lib\site-packages\IPython\core\ultratb.py", line 1143, in structured_traceback
  File "C:\Users\luis_\anaconda3\envs\tf-optuna2\lib\site-packages\IPython\core\ultratb.py", line 1082, in format_exception_as_a_whole
  File "C:\Users\luis_\anaconda3\envs\tf-optuna2\lib\site-packages\IPython\core\ultratb.py", line 382, in find_recursion
TypeError: object of type 'NoneType' has no len()
During handling of the above exception, another exception occurred:
Traceback (most recent call last):
  File "C:\Users\luis_\anaconda3\envs\tf-optuna2\lib\site-packages\IPython\core\interactiveshell.py", line 2077, in showtraceback
AttributeError: 'TypeError' object has no attribute '_render_traceback_'
During handling of the above exception, another exception occurred:
Traceback (most recent call last):
  File "C:\Users\luis_\anaconda3\envs\tf-optuna2\lib\site-packages\IPython\core\ultratb.py", line 1101, in get_records
  File "C:\Users\luis_\anaconda3\envs\tf-optuna2\lib\site-packages\IPython\core\ultratb.py", line 248, in wrapped
  File "C:\Users\luis_\anaconda3\envs\tf-optuna2\lib\site-packages\IPython\core\ultratb.py", line 281, in _fixed_getinnerframes
  File "C:\Users\luis_\anaconda3\envs\tf-optuna2\lib\inspect.py", line 1502, in getinnerframes
    frameinfo = (tb.tb_frame,) + getframeinfo(tb, context)
  File "C:\Users\luis_\anaconda3\envs\tf-optuna2\lib\inspect.py", line 1460, in getframeinfo
    filename = getsourcefile(frame) or getfile(frame)
  File "C:\Users\luis_\anaconda3\envs\tf-optuna2\lib\inspect.py", line 696, in getsourcefile
    if getattr(getmodule(object, filename), '__loader__', None) is not None:
  File "C:\Users\luis_\anaconda3\envs\tf-optuna2\lib\inspect.py", line 733, in getmodule
    if ismodule(module) and hasattr(module, '__file__'):
  File "C:\Users\luis_\anaconda3\envs\tf-optuna2\lib\site-packages\tensorflow\__init__.py", line 50, in __getattr__
    from tensorflow._api.v1 import layers
  File "C:\Users\luis_\anaconda3\envs\tf-optuna2\lib\site-packages\tensorflow\__init__.py", line 44, in _load
    from tensorflow._api.v1 import feature_column
  File "C:\Users\luis_\anaconda3\envs\tf-optuna2\lib\importlib\__init__.py", line 127, in import_module
    return _bootstrap._gcd_import(name[level:], package, level)
  File "<frozen importlib._bootstrap>", line 1006, in _gcd_import
  File "<frozen importlib._bootstrap>", line 983, in _find_and_load
  File "<frozen importlib._bootstrap>", line 953, in _find_and_load_unlocked
  File "<frozen importlib._bootstrap>", line 219, in _call_with_frames_removed
  File "<frozen importlib._bootstrap>", line 1006, in _gcd_import
  File "<frozen importlib._bootstrap>", line 983, in _find_and_load
  File "<frozen importlib._bootstrap>", line 965, in _find_and_load_unlocked
ModuleNotFoundError: No module named 'tensorflow_core'
ERROR:root:Internal Python error in the inspect module.
Below is the traceback from this internal error.
ERROR:root:Internal Python error in the inspect module.
Below is the traceback from this internal error.
ERROR:root:Internal Python error in the inspect module.
Below is the traceback from this internal error.
Traceback (most recent call last):
  File "C:\Users\luis_\anaconda3\envs\tf-optuna2\lib\site-packages\IPython\core\interactiveshell.py", line 3457, in run_code
  File "C:\Users\luis_\AppData\Local\Temp\ipykernel_21356\4207740377.py", line 1, in <module>
    from tensorflow.keras.models import Sequential
  File "C:\Users\luis_\anaconda3\envs\tf-optuna2\lib\site-packages\tensorflow\__init__.py", line 50, in __getattr__
    from tensorflow._api.v1 import layers
  File "C:\Users\luis_\anaconda3\envs\tf-optuna2\lib\site-packages\tensorflow\__init__.py", line 44, in _load
    from tensorflow._api.v1 import feature_column
  File "C:\Users\luis_\anaconda3\envs\tf-optuna2\lib\importlib\__init__.py", line 127, in import_module
    return _bootstrap._gcd_import(name[level:], package, level)
ModuleNotFoundError: No module named 'tensorflow_core'
During handling of the above exception, another exception occurred:
Traceback (most recent call last):
  File "C:\Users\luis_\anaconda3\envs\tf-optuna2\lib\site-packages\IPython\core\interactiveshell.py", line 2077, in showtraceback
AttributeError: 'ModuleNotFoundError' object has no attribute '_render_traceback_'
During handling of the above exception, another exception occurred:
Traceback (most recent call last):
  File "C:\Users\luis_\anaconda3\envs\tf-optuna2\lib\site-packages\IPython\core\ultratb.py", line 1101, in get_records
  File "C:\Users\luis_\anaconda3\envs\tf-optuna2\lib\site-packages\IPython\core\ultratb.py", line 248, in wrapped
  File "C:\Users\luis_\anaconda3\envs\tf-optuna2\lib\site-packages\IPython\core\ultratb.py", line 281, in _fixed_getinnerframes
  File "C:\Users\luis_\anaconda3\envs\tf-optuna2\lib\inspect.py", line 1502, in getinnerframes
    frameinfo = (tb.tb_frame,) + getframeinfo(tb, context)
  File "C:\Users\luis_\anaconda3\envs\tf-optuna2\lib\inspect.py", line 1460, in getframeinfo
    filename = getsourcefile(frame) or getfile(frame)
  File "C:\Users\luis_\anaconda3\envs\tf-optuna2\lib\inspect.py", line 696, in getsourcefile
    if getattr(getmodule(object, filename), '__loader__', None) is not None:
  File "C:\Users\luis_\anaconda3\envs\tf-optuna2\lib\inspect.py", line 733, in getmodule
    if ismodule(module) and hasattr(module, '__file__'):
  File "C:\Users\luis_\anaconda3\envs\tf-optuna2\lib\site-packages\tensorflow\__init__.py", line 50, in __getattr__
    from tensorflow._api.v1 import layers
  File "C:\Users\luis_\anaconda3\envs\tf-optuna2\lib\site-packages\tensorflow\__init__.py", line 44, in _load
    from tensorflow._api.v1 import feature_column
  File "C:\Users\luis_\anaconda3\envs\tf-optuna2\lib\importlib\__init__.py", line 127, in import_module
    return _bootstrap._gcd_import(name[level:], package, level)
  File "<frozen importlib._bootstrap>", line 1006, in _gcd_import
  File "<frozen importlib._bootstrap>", line 983, in _find_and_load
  File "<frozen importlib._bootstrap>", line 953, in _find_and_load_unlocked
  File "<frozen importlib._bootstrap>", line 219, in _call_with_frames_removed
  File "<frozen importlib._bootstrap>", line 1006, in _gcd_import
  File "<frozen importlib._bootstrap>", line 983, in _find_and_load
  File "<frozen importlib._bootstrap>", line 965, in _find_and_load_unlocked
ModuleNotFoundError: No module named 'tensorflow_core'
ERROR! Session/line number was not unique in database. History logging moved to new session 541
Traceback (most recent call last):
  File "C:\Users\luis_\anaconda3\envs\tf-optuna2\lib\site-packages\IPython\core\interactiveshell.py", line 3457, in run_code
  File "C:\Users\luis_\AppData\Local\Temp\ipykernel_21356\4207740377.py", line 1, in <module>
    from tensorflow.keras.models import Sequential
  File "C:\Users\luis_\anaconda3\envs\tf-optuna2\lib\site-packages\tensorflow\__init__.py", line 50, in __getattr__
    from tensorflow._api.v1 import layers
  File "C:\Users\luis_\anaconda3\envs\tf-optuna2\lib\site-packages\tensorflow\__init__.py", line 44, in _load
    from tensorflow._api.v1 import feature_column
  File "C:\Users\luis_\anaconda3\envs\tf-optuna2\lib\importlib\__init__.py", line 127, in import_module
    return _bootstrap._gcd_import(name[level:], package, level)
ModuleNotFoundError: No module named 'tensorflow_core'
During handling of the above exception, another exception occurred:
Traceback (most recent call last):
  File "C:\Users\luis_\anaconda3\envs\tf-optuna2\lib\site-packages\IPython\core\interactiveshell.py", line 2077, in showtraceback
AttributeError: 'ModuleNotFoundError' object has no attribute '_render_traceback_'
During handling of the above exception, another exception occurred:
Traceback (most recent call last):
  File "C:\Users\luis_\anaconda3\envs\tf-optuna2\lib\site-packages\IPython\core\interactiveshell.py", line 3377, in run_ast_nodes
  File "C:\Users\luis_\anaconda3\envs\tf-optuna2\lib\site-packages\IPython\core\interactiveshell.py", line 3474, in run_code
  File "C:\Users\luis_\anaconda3\envs\tf-optuna2\lib\site-packages\IPython\core\interactiveshell.py", line 2080, in showtraceback
  File "C:\Users\luis_\anaconda3\envs\tf-optuna2\lib\site-packages\IPython\core\ultratb.py", line 1368, in structured_traceback
  File "C:\Users\luis_\anaconda3\envs\tf-optuna2\lib\site-packages\IPython\core\ultratb.py", line 1268, in structured_traceback
  File "C:\Users\luis_\anaconda3\envs\tf-optuna2\lib\site-packages\IPython\core\ultratb.py", line 1125, in structured_traceback
  File "C:\Users\luis_\anaconda3\envs\tf-optuna2\lib\site-packages\IPython\core\ultratb.py", line 1082, in format_exception_as_a_whole
  File "C:\Users\luis_\anaconda3\envs\tf-optuna2\lib\site-packages\IPython\core\ultratb.py", line 382, in find_recursion
TypeError: object of type 'NoneType' has no len()
During handling of the above exception, another exception occurred:
Traceback (most recent call last):
  File "C:\Users\luis_\anaconda3\envs\tf-optuna2\lib\site-packages\IPython\core\interactiveshell.py", line 2077, in showtraceback
AttributeError: 'TypeError' object has no attribute '_render_traceback_'
During handling of the above exception, another exception occurred:
Traceback (most recent call last):
  File "C:\Users\luis_\anaconda3\envs\tf-optuna2\lib\site-packages\IPython\core\ultratb.py", line 1101, in get_records
  File "C:\Users\luis_\anaconda3\envs\tf-optuna2\lib\site-packages\IPython\core\ultratb.py", line 248, in wrapped
  File "C:\Users\luis_\anaconda3\envs\tf-optuna2\lib\site-packages\IPython\core\ultratb.py", line 281, in _fixed_getinnerframes
  File "C:\Users\luis_\anaconda3\envs\tf-optuna2\lib\inspect.py", line 1502, in getinnerframes
    frameinfo = (tb.tb_frame,) + getframeinfo(tb, context)
  File "C:\Users\luis_\anaconda3\envs\tf-optuna2\lib\inspect.py", line 1460, in getframeinfo
    filename = getsourcefile(frame) or getfile(frame)
  File "C:\Users\luis_\anaconda3\envs\tf-optuna2\lib\inspect.py", line 696, in getsourcefile
    if getattr(getmodule(object, filename), '__loader__', None) is not None:
  File "C:\Users\luis_\anaconda3\envs\tf-optuna2\lib\inspect.py", line 733, in getmodule
    if ismodule(module) and hasattr(module, '__file__'):
  File "C:\Users\luis_\anaconda3\envs\tf-optuna2\lib\site-packages\tensorflow\__init__.py", line 50, in __getattr__
    from tensorflow._api.v1 import layers
  File "C:\Users\luis_\anaconda3\envs\tf-optuna2\lib\site-packages\tensorflow\__init__.py", line 44, in _load
    from tensorflow._api.v1 import feature_column
  File "C:\Users\luis_\anaconda3\envs\tf-optuna2\lib\importlib\__init__.py", line 127, in import_module
    return _bootstrap._gcd_import(name[level:], package, level)
  File "<frozen importlib._bootstrap>", line 1006, in _gcd_import
  File "<frozen importlib._bootstrap>", line 983, in _find_and_load
  File "<frozen importlib._bootstrap>", line 953, in _find_and_load_unlocked
  File "<frozen importlib._bootstrap>", line 219, in _call_with_frames_removed
  File "<frozen importlib._bootstrap>", line 1006, in _gcd_import
  File "<frozen importlib._bootstrap>", line 983, in _find_and_load
  File "<frozen importlib._bootstrap>", line 965, in _find_and_load_unlocked
ModuleNotFoundError: No module named 'tensorflow_core'
Traceback (most recent call last):
  File "C:\Users\luis_\anaconda3\envs\tf-optuna2\lib\site-packages\IPython\core\interactiveshell.py", line 3457, in run_code
  File "C:\Users\luis_\AppData\Local\Temp\ipykernel_21356\4207740377.py", line 1, in <module>
    from tensorflow.keras.models import Sequential
  File "C:\Users\luis_\anaconda3\envs\tf-optuna2\lib\site-packages\tensorflow\__init__.py", line 50, in __getattr__
    from tensorflow._api.v1 import layers
  File "C:\Users\luis_\anaconda3\envs\tf-optuna2\lib\site-packages\tensorflow\__init__.py", line 44, in _load
    from tensorflow._api.v1 import feature_column
  File "C:\Users\luis_\anaconda3\envs\tf-optuna2\lib\importlib\__init__.py", line 127, in import_module
    return _bootstrap._gcd_import(name[level:], package, level)
ModuleNotFoundError: No module named 'tensorflow_core'
During handling of the above exception, another exception occurred:
Traceback (most recent call last):
  File "C:\Users\luis_\anaconda3\envs\tf-optuna2\lib\site-packages\IPython\core\interactiveshell.py", line 2077, in showtraceback
AttributeError: 'ModuleNotFoundError' object has no attribute '_render_traceback_'
During handling of the above exception, another exception occurred:
Traceback (most recent call last):
  File "C:\Users\luis_\anaconda3\envs\tf-optuna2\lib\site-packages\IPython\core\interactiveshell.py", line 3377, in run_ast_nodes
  File "C:\Users\luis_\anaconda3\envs\tf-optuna2\lib\site-packages\IPython\core\interactiveshell.py", line 3474, in run_code
  File "C:\Users\luis_\anaconda3\envs\tf-optuna2\lib\site-packages\IPython\core\interactiveshell.py", line 2080, in showtraceback
  File "C:\Users\luis_\anaconda3\envs\tf-optuna2\lib\site-packages\IPython\core\ultratb.py", line 1368, in structured_traceback
  File "C:\Users\luis_\anaconda3\envs\tf-optuna2\lib\site-packages\IPython\core\ultratb.py", line 1268, in structured_traceback
  File "C:\Users\luis_\anaconda3\envs\tf-optuna2\lib\site-packages\IPython\core\ultratb.py", line 1125, in structured_traceback
  File "C:\Users\luis_\anaconda3\envs\tf-optuna2\lib\site-packages\IPython\core\ultratb.py", line 1082, in format_exception_as_a_whole
  File "C:\Users\luis_\anaconda3\envs\tf-optuna2\lib\site-packages\IPython\core\ultratb.py", line 382, in find_recursion
TypeError: object of type 'NoneType' has no len()
During handling of the above exception, another exception occurred:
Traceback (most recent call last):
  File "C:\Users\luis_\anaconda3\envs\tf-optuna2\lib\site-packages\IPython\core\interactiveshell.py", line 2077, in showtraceback
AttributeError: 'TypeError' object has no attribute '_render_traceback_'
During handling of the above exception, another exception occurred:
Traceback (most recent call last):
  File "C:\Users\luis_\anaconda3\envs\tf-optuna2\lib\site-packages\IPython\core\interactiveshell.py", line 2960, in _run_cell
  File "C:\Users\luis_\anaconda3\envs\tf-optuna2\lib\site-packages\IPython\core\async_helpers.py", line 78, in _pseudo_sync_runner
  File "C:\Users\luis_\anaconda3\envs\tf-optuna2\lib\site-packages\IPython\core\interactiveshell.py", line 3186, in run_cell_async
  File "C:\Users\luis_\anaconda3\envs\tf-optuna2\lib\site-packages\IPython\core\interactiveshell.py", line 3396, in run_ast_nodes
  File "C:\Users\luis_\anaconda3\envs\tf-optuna2\lib\site-packages\IPython\core\interactiveshell.py", line 2080, in showtraceback
  File "C:\Users\luis_\anaconda3\envs\tf-optuna2\lib\site-packages\IPython\core\ultratb.py", line 1368, in structured_traceback
  File "C:\Users\luis_\anaconda3\envs\tf-optuna2\lib\site-packages\IPython\core\ultratb.py", line 1268, in structured_traceback
  File "C:\Users\luis_\anaconda3\envs\tf-optuna2\lib\site-packages\IPython\core\ultratb.py", line 1143, in structured_traceback
  File "C:\Users\luis_\anaconda3\envs\tf-optuna2\lib\site-packages\IPython\core\ultratb.py", line 1082, in format_exception_as_a_whole
  File "C:\Users\luis_\anaconda3\envs\tf-optuna2\lib\site-packages\IPython\core\ultratb.py", line 382, in find_recursion
TypeError: object of type 'NoneType' has no len()
During handling of the above exception, another exception occurred:
Traceback (most recent call last):
  File "C:\Users\luis_\anaconda3\envs\tf-optuna2\lib\site-packages\IPython\core\interactiveshell.py", line 2077, in showtraceback
AttributeError: 'TypeError' object has no attribute '_render_traceback_'
During handling of the above exception, another exception occurred:
Traceback (most recent call last):
  File "C:\Users\luis_\anaconda3\envs\tf-optuna2\lib\site-packages\IPython\core\ultratb.py", line 1101, in get_records
  File "C:\Users\luis_\anaconda3\envs\tf-optuna2\lib\site-packages\IPython\core\ultratb.py", line 248, in wrapped
  File "C:\Users\luis_\anaconda3\envs\tf-optuna2\lib\site-packages\IPython\core\ultratb.py", line 281, in _fixed_getinnerframes
  File "C:\Users\luis_\anaconda3\envs\tf-optuna2\lib\inspect.py", line 1502, in getinnerframes
    frameinfo = (tb.tb_frame,) + getframeinfo(tb, context)
  File "C:\Users\luis_\anaconda3\envs\tf-optuna2\lib\inspect.py", line 1460, in getframeinfo
    filename = getsourcefile(frame) or getfile(frame)
  File "C:\Users\luis_\anaconda3\envs\tf-optuna2\lib\inspect.py", line 696, in getsourcefile
    if getattr(getmodule(object, filename), '__loader__', None) is not None:
  File "C:\Users\luis_\anaconda3\envs\tf-optuna2\lib\inspect.py", line 733, in getmodule
    if ismodule(module) and hasattr(module, '__file__'):
  File "C:\Users\luis_\anaconda3\envs\tf-optuna2\lib\site-packages\tensorflow\__init__.py", line 50, in __getattr__
    from tensorflow._api.v1 import layers
  File "C:\Users\luis_\anaconda3\envs\tf-optuna2\lib\site-packages\tensorflow\__init__.py", line 44, in _load
    from tensorflow._api.v1 import feature_column
  File "C:\Users\luis_\anaconda3\envs\tf-optuna2\lib\importlib\__init__.py", line 127, in import_module
    return _bootstrap._gcd_import(name[level:], package, level)
  File "<frozen importlib._bootstrap>", line 1006, in _gcd_import
  File "<frozen importlib._bootstrap>", line 983, in _find_and_load
  File "<frozen importlib._bootstrap>", line 953, in _find_and_load_unlocked
  File "<frozen importlib._bootstrap>", line 219, in _call_with_frames_removed
  File "<frozen importlib._bootstrap>", line 1006, in _gcd_import
  File "<frozen importlib._bootstrap>", line 983, in _find_and_load
  File "<frozen importlib._bootstrap>", line 965, in _find_and_load_unlocked
ModuleNotFoundError: No module named 'tensorflow_core'
ERROR:root:Internal Python error in the inspect module.
Below is the traceback from this internal error.
ERROR:root:Internal Python error in the inspect module.
Below is the traceback from this internal error.
ERROR:root:Internal Python error in the inspect module.
Below is the traceback from this internal error.
ERROR! Session/line number was not unique in database. History logging moved to new session 542
Traceback (most recent call last):
  File "C:\Users\luis_\anaconda3\envs\tf-optuna2\lib\site-packages\IPython\core\interactiveshell.py", line 3457, in run_code
  File "C:\Users\luis_\AppData\Local\Temp\ipykernel_21356\985137052.py", line 1, in <module>
    tf.__version__
AttributeError: module 'tensorflow' has no attribute '__version__'
During handling of the above exception, another exception occurred:
Traceback (most recent call last):
  File "C:\Users\luis_\anaconda3\envs\tf-optuna2\lib\site-packages\IPython\core\interactiveshell.py", line 2077, in showtraceback
AttributeError: 'AttributeError' object has no attribute '_render_traceback_'
During handling of the above exception, another exception occurred:
Traceback (most recent call last):
  File "C:\Users\luis_\anaconda3\envs\tf-optuna2\lib\site-packages\IPython\core\ultratb.py", line 1101, in get_records
  File "C:\Users\luis_\anaconda3\envs\tf-optuna2\lib\site-packages\IPython\core\ultratb.py", line 248, in wrapped
  File "C:\Users\luis_\anaconda3\envs\tf-optuna2\lib\site-packages\IPython\core\ultratb.py", line 281, in _fixed_getinnerframes
  File "C:\Users\luis_\anaconda3\envs\tf-optuna2\lib\inspect.py", line 1502, in getinnerframes
    frameinfo = (tb.tb_frame,) + getframeinfo(tb, context)
  File "C:\Users\luis_\anaconda3\envs\tf-optuna2\lib\inspect.py", line 1460, in getframeinfo
    filename = getsourcefile(frame) or getfile(frame)
  File "C:\Users\luis_\anaconda3\envs\tf-optuna2\lib\inspect.py", line 696, in getsourcefile
    if getattr(getmodule(object, filename), '__loader__', None) is not None:
  File "C:\Users\luis_\anaconda3\envs\tf-optuna2\lib\inspect.py", line 733, in getmodule
    if ismodule(module) and hasattr(module, '__file__'):
  File "C:\Users\luis_\anaconda3\envs\tf-optuna2\lib\site-packages\tensorflow\__init__.py", line 50, in __getattr__
    from tensorflow._api.v1 import layers
  File "C:\Users\luis_\anaconda3\envs\tf-optuna2\lib\site-packages\tensorflow\__init__.py", line 44, in _load
    from tensorflow._api.v1 import feature_column
  File "C:\Users\luis_\anaconda3\envs\tf-optuna2\lib\importlib\__init__.py", line 127, in import_module
    return _bootstrap._gcd_import(name[level:], package, level)
  File "<frozen importlib._bootstrap>", line 1006, in _gcd_import
  File "<frozen importlib._bootstrap>", line 983, in _find_and_load
  File "<frozen importlib._bootstrap>", line 953, in _find_and_load_unlocked
  File "<frozen importlib._bootstrap>", line 219, in _call_with_frames_removed
  File "<frozen importlib._bootstrap>", line 1006, in _gcd_import
  File "<frozen importlib._bootstrap>", line 983, in _find_and_load
  File "<frozen importlib._bootstrap>", line 965, in _find_and_load_unlocked
ModuleNotFoundError: No module named 'tensorflow_core'
Traceback (most recent call last):
  File "C:\Users\luis_\anaconda3\envs\tf-optuna2\lib\site-packages\IPython\core\interactiveshell.py", line 3457, in run_code
  File "C:\Users\luis_\AppData\Local\Temp\ipykernel_21356\985137052.py", line 1, in <module>
    tf.__version__
AttributeError: module 'tensorflow' has no attribute '__version__'
During handling of the above exception, another exception occurred:
Traceback (most recent call last):
  File "C:\Users\luis_\anaconda3\envs\tf-optuna2\lib\site-packages\IPython\core\interactiveshell.py", line 2077, in showtraceback
AttributeError: 'AttributeError' object has no attribute '_render_traceback_'
During handling of the above exception, another exception occurred:
Traceback (most recent call last):
  File "C:\Users\luis_\anaconda3\envs\tf-optuna2\lib\site-packages\IPython\core\interactiveshell.py", line 3377, in run_ast_nodes
  File "C:\Users\luis_\anaconda3\envs\tf-optuna2\lib\site-packages\IPython\core\interactiveshell.py", line 3474, in run_code
  File "C:\Users\luis_\anaconda3\envs\tf-optuna2\lib\site-packages\IPython\core\interactiveshell.py", line 2080, in showtraceback
  File "C:\Users\luis_\anaconda3\envs\tf-optuna2\lib\site-packages\IPython\core\ultratb.py", line 1368, in structured_traceback
  File "C:\Users\luis_\anaconda3\envs\tf-optuna2\lib\site-packages\IPython\core\ultratb.py", line 1268, in structured_traceback
  File "C:\Users\luis_\anaconda3\envs\tf-optuna2\lib\site-packages\IPython\core\ultratb.py", line 1125, in structured_traceback
  File "C:\Users\luis_\anaconda3\envs\tf-optuna2\lib\site-packages\IPython\core\ultratb.py", line 1082, in format_exception_as_a_whole
  File "C:\Users\luis_\anaconda3\envs\tf-optuna2\lib\site-packages\IPython\core\ultratb.py", line 382, in find_recursion
TypeError: object of type 'NoneType' has no len()
During handling of the above exception, another exception occurred:
Traceback (most recent call last):
  File "C:\Users\luis_\anaconda3\envs\tf-optuna2\lib\site-packages\IPython\core\interactiveshell.py", line 2077, in showtraceback
AttributeError: 'TypeError' object has no attribute '_render_traceback_'
During handling of the above exception, another exception occurred:
Traceback (most recent call last):
  File "C:\Users\luis_\anaconda3\envs\tf-optuna2\lib\site-packages\IPython\core\ultratb.py", line 1101, in get_records
  File "C:\Users\luis_\anaconda3\envs\tf-optuna2\lib\site-packages\IPython\core\ultratb.py", line 248, in wrapped
  File "C:\Users\luis_\anaconda3\envs\tf-optuna2\lib\site-packages\IPython\core\ultratb.py", line 281, in _fixed_getinnerframes
  File "C:\Users\luis_\anaconda3\envs\tf-optuna2\lib\inspect.py", line 1502, in getinnerframes
    frameinfo = (tb.tb_frame,) + getframeinfo(tb, context)
  File "C:\Users\luis_\anaconda3\envs\tf-optuna2\lib\inspect.py", line 1460, in getframeinfo
    filename = getsourcefile(frame) or getfile(frame)
  File "C:\Users\luis_\anaconda3\envs\tf-optuna2\lib\inspect.py", line 696, in getsourcefile
    if getattr(getmodule(object, filename), '__loader__', None) is not None:
  File "C:\Users\luis_\anaconda3\envs\tf-optuna2\lib\inspect.py", line 733, in getmodule
    if ismodule(module) and hasattr(module, '__file__'):
  File "C:\Users\luis_\anaconda3\envs\tf-optuna2\lib\site-packages\tensorflow\__init__.py", line 50, in __getattr__
    from tensorflow._api.v1 import layers
  File "C:\Users\luis_\anaconda3\envs\tf-optuna2\lib\site-packages\tensorflow\__init__.py", line 44, in _load
    from tensorflow._api.v1 import feature_column
  File "C:\Users\luis_\anaconda3\envs\tf-optuna2\lib\importlib\__init__.py", line 127, in import_module
    return _bootstrap._gcd_import(name[level:], package, level)
  File "<frozen importlib._bootstrap>", line 1006, in _gcd_import
  File "<frozen importlib._bootstrap>", line 983, in _find_and_load
  File "<frozen importlib._bootstrap>", line 953, in _find_and_load_unlocked
  File "<frozen importlib._bootstrap>", line 219, in _call_with_frames_removed
  File "<frozen importlib._bootstrap>", line 1006, in _gcd_import
  File "<frozen importlib._bootstrap>", line 983, in _find_and_load
  File "<frozen importlib._bootstrap>", line 965, in _find_and_load_unlocked
ModuleNotFoundError: No module named 'tensorflow_core'
Traceback (most recent call last):
  File "C:\Users\luis_\anaconda3\envs\tf-optuna2\lib\site-packages\IPython\core\interactiveshell.py", line 3457, in run_code
  File "C:\Users\luis_\AppData\Local\Temp\ipykernel_21356\985137052.py", line 1, in <module>
    tf.__version__
AttributeError: module 'tensorflow' has no attribute '__version__'
During handling of the above exception, another exception occurred:
Traceback (most recent call last):
  File "C:\Users\luis_\anaconda3\envs\tf-optuna2\lib\site-packages\IPython\core\interactiveshell.py", line 2077, in showtraceback
AttributeError: 'AttributeError' object has no attribute '_render_traceback_'
During handling of the above exception, another exception occurred:
Traceback (most recent call last):
  File "C:\Users\luis_\anaconda3\envs\tf-optuna2\lib\site-packages\IPython\core\interactiveshell.py", line 3377, in run_ast_nodes
  File "C:\Users\luis_\anaconda3\envs\tf-optuna2\lib\site-packages\IPython\core\interactiveshell.py", line 3474, in run_code
  File "C:\Users\luis_\anaconda3\envs\tf-optuna2\lib\site-packages\IPython\core\interactiveshell.py", line 2080, in showtraceback
  File "C:\Users\luis_\anaconda3\envs\tf-optuna2\lib\site-packages\IPython\core\ultratb.py", line 1368, in structured_traceback
  File "C:\Users\luis_\anaconda3\envs\tf-optuna2\lib\site-packages\IPython\core\ultratb.py", line 1268, in structured_traceback
  File "C:\Users\luis_\anaconda3\envs\tf-optuna2\lib\site-packages\IPython\core\ultratb.py", line 1125, in structured_traceback
  File "C:\Users\luis_\anaconda3\envs\tf-optuna2\lib\site-packages\IPython\core\ultratb.py", line 1082, in format_exception_as_a_whole
  File "C:\Users\luis_\anaconda3\envs\tf-optuna2\lib\site-packages\IPython\core\ultratb.py", line 382, in find_recursion
TypeError: object of type 'NoneType' has no len()
During handling of the above exception, another exception occurred:
Traceback (most recent call last):
  File "C:\Users\luis_\anaconda3\envs\tf-optuna2\lib\site-packages\IPython\core\interactiveshell.py", line 2077, in showtraceback
AttributeError: 'TypeError' object has no attribute '_render_traceback_'
During handling of the above exception, another exception occurred:
Traceback (most recent call last):
  File "C:\Users\luis_\anaconda3\envs\tf-optuna2\lib\site-packages\IPython\core\interactiveshell.py", line 2960, in _run_cell
  File "C:\Users\luis_\anaconda3\envs\tf-optuna2\lib\site-packages\IPython\core\async_helpers.py", line 78, in _pseudo_sync_runner
  File "C:\Users\luis_\anaconda3\envs\tf-optuna2\lib\site-packages\IPython\core\interactiveshell.py", line 3186, in run_cell_async
  File "C:\Users\luis_\anaconda3\envs\tf-optuna2\lib\site-packages\IPython\core\interactiveshell.py", line 3396, in run_ast_nodes
  File "C:\Users\luis_\anaconda3\envs\tf-optuna2\lib\site-packages\IPython\core\interactiveshell.py", line 2080, in showtraceback
  File "C:\Users\luis_\anaconda3\envs\tf-optuna2\lib\site-packages\IPython\core\ultratb.py", line 1368, in structured_traceback
  File "C:\Users\luis_\anaconda3\envs\tf-optuna2\lib\site-packages\IPython\core\ultratb.py", line 1268, in structured_traceback
  File "C:\Users\luis_\anaconda3\envs\tf-optuna2\lib\site-packages\IPython\core\ultratb.py", line 1143, in structured_traceback
  File "C:\Users\luis_\anaconda3\envs\tf-optuna2\lib\site-packages\IPython\core\ultratb.py", line 1082, in format_exception_as_a_whole
  File "C:\Users\luis_\anaconda3\envs\tf-optuna2\lib\site-packages\IPython\core\ultratb.py", line 382, in find_recursion
TypeError: object of type 'NoneType' has no len()
During handling of the above exception, another exception occurred:
Traceback (most recent call last):
  File "C:\Users\luis_\anaconda3\envs\tf-optuna2\lib\site-packages\IPython\core\interactiveshell.py", line 2077, in showtraceback
AttributeError: 'TypeError' object has no attribute '_render_traceback_'
During handling of the above exception, another exception occurred:
Traceback (most recent call last):
  File "C:\Users\luis_\anaconda3\envs\tf-optuna2\lib\site-packages\IPython\core\ultratb.py", line 1101, in get_records
  File "C:\Users\luis_\anaconda3\envs\tf-optuna2\lib\site-packages\IPython\core\ultratb.py", line 248, in wrapped
  File "C:\Users\luis_\anaconda3\envs\tf-optuna2\lib\site-packages\IPython\core\ultratb.py", line 281, in _fixed_getinnerframes
  File "C:\Users\luis_\anaconda3\envs\tf-optuna2\lib\inspect.py", line 1502, in getinnerframes
    frameinfo = (tb.tb_frame,) + getframeinfo(tb, context)
  File "C:\Users\luis_\anaconda3\envs\tf-optuna2\lib\inspect.py", line 1460, in getframeinfo
    filename = getsourcefile(frame) or getfile(frame)
  File "C:\Users\luis_\anaconda3\envs\tf-optuna2\lib\inspect.py", line 696, in getsourcefile
    if getattr(getmodule(object, filename), '__loader__', None) is not None:
  File "C:\Users\luis_\anaconda3\envs\tf-optuna2\lib\inspect.py", line 733, in getmodule
    if ismodule(module) and hasattr(module, '__file__'):
  File "C:\Users\luis_\anaconda3\envs\tf-optuna2\lib\site-packages\tensorflow\__init__.py", line 50, in __getattr__
    from tensorflow._api.v1 import layers
  File "C:\Users\luis_\anaconda3\envs\tf-optuna2\lib\site-packages\tensorflow\__init__.py", line 44, in _load
    from tensorflow._api.v1 import feature_column
  File "C:\Users\luis_\anaconda3\envs\tf-optuna2\lib\importlib\__init__.py", line 127, in import_module
    return _bootstrap._gcd_import(name[level:], package, level)
  File "<frozen importlib._bootstrap>", line 1006, in _gcd_import
  File "<frozen importlib._bootstrap>", line 983, in _find_and_load
  File "<frozen importlib._bootstrap>", line 953, in _find_and_load_unlocked
  File "<frozen importlib._bootstrap>", line 219, in _call_with_frames_removed
  File "<frozen importlib._bootstrap>", line 1006, in _gcd_import
  File "<frozen importlib._bootstrap>", line 983, in _find_and_load
  File "<frozen importlib._bootstrap>", line 965, in _find_and_load_unlocked
ModuleNotFoundError: No module named 'tensorflow_core'
ERROR:root:Internal Python error in the inspect module.
Below is the traceback from this internal error.
ERROR:root:Internal Python error in the inspect module.
Below is the traceback from this internal error.
ERROR:root:Internal Python error in the inspect module.
